<!DOCTYPE html>
<html lang="en">
<head>
    <meta charset="UTF-8">
    <title>Title</title>
</head>
<body>
<!--
Generator函数
2020年3月18日13:10:00
-->

</body>
</html>


<script type="text/javascript">

    let log = (...filed) => {
        const { log } = console
        log('\t', ...filed)
    }

    // Generator 函数返回的遍历器对象，都有一个throw方法，可以在函数体外抛出错误，然后在 Generator 函数体内捕获。
    // 第一个例子
    let g = function * () {
        try {
            yield
        } catch (e) {
            console.log('内部捕获', e)
        }
    }

    let i = g()
    i.next()

    try {
        i.throw('a')
        console.log('输出1')
        i.throw('b')
        console.log('输出2')
    } catch (e) {
        console.log('外部捕获', e)
    }
    // 内部捕获 a
    // 输出1
    // 外部捕获 b
    // 分析：第一次异常，可以有generator内部捕获异常，然后处理，然后输出1,第二次异常，generator捕获次数用完了，就调用外部的捕获异常。

    // 第二个例子 ：  throw方法可以接受一个参数，该参数会被catch语句接收，建议抛出Error对象的实例。

    let gen = function * () {
        try {
            yield
        } catch (e) {
            console.log(e)
        }
    }

    let result1 = gen()
    result1.next()
    result1.throw(new Error('出错了！'))
    // Error: 出错了！(…)

    // 第三个例子： 如果generator函数内部没有部署try catch，那么throw方法抛出的异常，就会被外部的代码块捕获
    log('-------------')
    let gen2 = function * (num) {
        while (true) {
            yield num
            if (num > 5) {
                let i = num.push([NaN])
                console.log('内部异常')
            }
        }
    }

    let result2 = gen2(3)
    result2.next()
    try {
        result2.throw('我异常了')
    } catch (e) {
        console.log('外部异常', e)  // 外部异常
    }

    // 总结就是： generator内部捕获了异常，就用他内部的，用完了就用外部的

    // 第四个例子：都没有部署try catch
    let gen3 = function * () {
        yield console.log('hello')
        yield console.log('world')
    }

    let result3 = gen3()
    result3.next()
    //   result3.throw()  // 这里直接报错了
    //   log('程序异常了，我不会输出的')

    // 第五个例子： throw方法抛出的错误要被内部捕获，前提是必须至少执行过一次next方法。

    function * gen5 () {
        try {
            yield 1
        } catch (e) {
            console.log('内部捕获')
        }
    }

    let result5 = gen5()
    //  result5.throw(1);
    // Uncaught 1

    // 第六个例子： throw方法被捕获以后，会附带执行下一条yield表达式。也就是说，会附带执行一次next方法。

    let gen6 = function * gen () {
        try {
            yield console.log('a')
        } catch (e) {
            // ...
        }
        yield console.log('b')
        yield console.log('c')
    }

    let result6 = gen6()
    result6.next() // a
    result6.throw() // b
    result6.next() // c

    // homework: 搞清楚，yield具体卡停的位置

    // 第七个例子：一旦 Generator 执行过程中抛出错误，且没有被内部捕获，就不会再执行下去了。如果此后还调用next方法，
    function * gen7 () {
        yield 1
        console.log('throwing an exception')  // 3
        throw new Error('generator broke!')
        yield 2
        yield 3
    }

    function loggen (generator) {
        var v
        console.log('starting generator')// 1
        try {
            v = generator.next()
            console.log('第一次运行next方法', v)   // 2
        } catch (err) {
            console.log('捕捉错误', v)
        }
        try {
            v = generator.next()
            console.log('第二次运行next方法', v)
        } catch (err) {
            console.log('捕捉错误', v)  // 4
        }
        try {
            v = generator.next()
            console.log('第三次运行next方法', v)  // 5
        } catch (err) {
            console.log('捕捉错误', v)
        }
        console.log('caller done')   // 6
    }

    loggen(gen7())


</script>
