<!DOCTYPE html>
<html lang="en">
<head>
    <meta charset="UTF-8">
    <title>Title</title>
</head>
<body>
<!--
async
2020年3月19日10:15:42
-->

</body>
</html>


<script type="text/javascript">

    let log = (...filed) => {
        const { log } = console
        log('\t', ...filed)
    }

    // async函数的await命令后面，可以是 Promise 对象和原始类型的值（数值、字符串和布尔值，但这时会自动转成立即 resolved 的 Promise 对象）。

    // 例子一：正常的
    async function f () {
        return 'hello world'
    }

    f().then(value => log(value))    // hello World

    // 例子二： 报错的
    async function err () {
        throw new Error('错误')
    }

    err().then(value => log('我不会被输出')).catch(e => log('我错了', e))

    /*
    Promise 对象的状态变化
    async函数返回的 Promise 对象，必须等到内部所有await命令后面的 Promise 对象执行完，才会发生状态改变，
    除非遇到return语句或者抛出错误。也就是说，只有async函数内部的异步操作执行完，才会执行then方法指定的回调函数。
     */

    // await 命令
    // 正常情况下，await命令后面是一个 Promise 对象，返回该对象的结果。如果不是 Promise 对象，就直接返回对应的值。
    async function f2 () {
        // 等同于
        // return 123;
        return await 123
    }

    const result2 = f2()
    console.log(typeof result2, result2)  // object,promise
    // 结论，不管返回123 还是await 123都会封装成一个promise对象

    // 例子三 ：实现定时
    function sleep (interval) {
        return new Promise(resolve => {
            setTimeout(resolve, interval)
        })
    }

    // 用法
    async function one2FiveInAsync () {
        for (let i = 1; i <= 5; i++) {
            console.log(i)
            await sleep(1000)
        }
    }

    one2FiveInAsync()

    // 例子四： （1）看看出错的时候
    async function ferr () {
        // here: 这里并没有return ,但是被catch返回了结果
        await Promise.reject('出错了')
        await Promise.resolve('我也不会被输出')  // 如果出错不会被输出的
    }

    ferr()
        .then(v => console.log(v))
        .catch(e => console.log(e))
    // 出错了

    //例子五： 如何处理异常的情况(1)
    async function f5 () {
        try {
            await Promise.reject('出错5')
        } catch (e) {

        }
        return await Promise.resolve('我还是输出了5')
    }

    f5().then(res => log('结果：', res))

    //例子五： 如何处理异常的情况(2)e
    async function f6 () {
        await Promise.reject('出错6').catch(e => log(e))
        return await Promise.resolve('我还是输出了6')
    }

    f6().then(res => log('结果：', res))

    // 例子六： 多个await命令，可以统一藏在try,catch中

    function getAPromise (timeout = 1000) {
        return new Promise((resolve, reject) => {
            if (timeout > 1500) {
                setTimeout(reject, timeout, timeout)
            } else {
                setTimeout(resolve, timeout, timeout)
            }
        })
    }

    async function manyRequest () {
        try {
            const val1 = await getAPromise(2000)
            const val2 = await getAPromise()
            const val3 = 123
            return val3
        } catch (e) {
            log('错误：例子6')
        }
    }

    manyRequest().then(res => log('正确的时候',res)).catch(e => log('输出例子六的结果',e))


</script>
